<?xml version="1.0" encoding="utf-8"?>
<!-- This URDF was automatically created by SolidWorks to URDF Exporter! Originally created by Stephen Brawner (brawner@gmail.com) 
     Commit Version: 1.6.0-4-g7f85cfe  Build Version: 1.6.7995.38578
     For more information, please see http://wiki.ros.org/sw_urdf_exporter -->
<robot
  name="LRMate-200iD">
  <link
    name="Base">
    <inertial>
      <origin
        xyz="-0.00682678184455439 0.0804225935378344 0.00032167938539702"
        rpy="0 0 0" />
      <mass
        value="4.85328944881567" />
      <inertia
        ixx="0.0219866138695383"
        ixy="0.000143030504983191"
        ixz="0.000118504116957291"
        iyy="0.0228011824587363"
        iyz="3.06008744367205E-05"
        izz="0.0238292245301772" />
    </inertial>
    <visual>
      <origin
        xyz="0 0 0"
        rpy="0 0 0" />
      <geometry>
        <mesh
          filename="package://LRMate-200iD/meshes/base.stl" />
      </geometry>
      <material
        name="">
        <color
          rgba="0.792156862745098 0.819607843137255 0.933333333333333 1" />
      </material>
    </visual>
    <collision>
      <origin
        xyz="0 0 0"
        rpy="0 0 0" />
      <geometry>
        <mesh
          filename="package://LRMate-200iD/meshes/base.stl" />
      </geometry>
    </collision>
  </link>
  <link
    name="J1">
    <inertial>
      <origin
        xyz="0.0391912620989729 -0.000668128020168369 0.318431207963404"
        rpy="0 0 0" />
      <mass
        value="14.3548583797231" />
      <inertia
        ixx="0.905961667890462"
        ixy="-0.000630585508551185"
        ixz="-0.132429780051495"
        iyy="0.959094388040307"
        iyz="-0.00083158726434221"
        izz="0.132638947385101" />
    </inertial>
    <visual>
      <origin
        xyz="0 0 0"
        rpy="0 0 0" />
      <geometry>
        <mesh
          filename="package://LRMate-200iD/meshes/j1.stl" />
      </geometry>
      <material
        name="">
        <color
          rgba="0.792156862745098 0.819607843137255 0.933333333333333 1" />
      </material>
    </visual>
    <collision>
      <origin
        xyz="0 0 0"
        rpy="0 0 0" />
      <geometry>
        <mesh
          filename="package://LRMate-200iD/meshes/j1.stl" />
      </geometry>
    </collision>
  </link>
  <joint
    name="J1"
    type="revolute">
    <origin
      xyz="0 0 0.042741"
      rpy="0 0 0" />
    <parent
      link="Base" />
    <child
      link="J1" />
    <axis
      xyz="0 0 1" />
    <limit
      lower="-2.9671"
      upper="2.9671"
      effort="0"
      velocity="0" />
  </joint>
  <link
    name="J2">
    <inertial>
      <origin
        xyz="-0.00799341012139976 -0.00180144991268474 0.121256169355667"
        rpy="0 0 0" />
      <mass
        value="6.36136243537974" />
      <inertia
        ixx="0.106651294266549"
        ixy="8.06821595330544E-05"
        ixz="0.00145113826609404"
        iyy="0.087067768364476"
        iyz="-0.000557415213291903"
        izz="0.0317015606764394" />
    </inertial>
    <visual>
      <origin
        xyz="0 0 0"
        rpy="0 0 0" />
      <geometry>
        <mesh
          filename="package://LRMate-200iD/meshes/j2.stl" />
      </geometry>
      <material
        name="">
        <color
          rgba="0.792156862745098 0.819607843137255 0.933333333333333 1" />
      </material>
    </visual>
    <collision>
      <origin
        xyz="0 0 0"
        rpy="0 0 0" />
      <geometry>
        <mesh
          filename="package://LRMate-200iD/meshes/j2.stl" />
      </geometry>
    </collision>
  </link>
  <joint
    name="J2"
    type="revolute">
    <origin
      xyz="0.05 0 0.28726"
      rpy="0 0 0" />
    <parent
      link="J1" />
    <child
      link="J2" />
    <axis
      xyz="0 -1 0" />
    <limit
      lower="-2.5307"
      upper="1.7453"
      effort="0"
      velocity="0" />
  </joint>
  <link
    name="J3">
    <inertial>
      <origin
        xyz="0.00823675547404687 0.000680366444924521 0.0176458504878265"
        rpy="0 0 0" />
      <mass
        value="2.39426239864507" />
      <inertia
        ixx="0.00633472848658925"
        ixy="-4.95044602058742E-05"
        ixz="-0.000761354685999054"
        iyy="0.00732801950250117"
        iyz="-6.64725975554786E-05"
        izz="0.00726042509478913" />
    </inertial>
    <visual>
      <origin
        xyz="0 0 0"
        rpy="0 0 0" />
      <geometry>
        <mesh
          filename="package://LRMate-200iD/meshes/j3.stl" />
      </geometry>
      <material
        name="">
        <color
          rgba="0.792156862745098 0.819607843137255 0.933333333333333 1" />
      </material>
    </visual>
    <collision>
      <origin
        xyz="0 0 0"
        rpy="0 0 0" />
      <geometry>
        <mesh
          filename="package://LRMate-200iD/meshes/j3.stl" />
      </geometry>
    </collision>
  </link>
  <joint
    name="J3"
    type="revolute">
    <origin
      xyz="0 0 0.33"
      rpy="0 0 0" />
    <parent
      link="J2" />
    <child
      link="J3" />
    <axis
      xyz="0 -1 0" />
    <limit
      lower="-1.2217"
      upper="3.5779"
      effort="0"
      velocity="0" />
  </joint>
  <link
    name="J4">
    <inertial>
      <origin
        xyz="0.108898689131393 0.00891424227545998 0.0561499999934005"
        rpy="0 0 0" />
      <mass
        value="0.000826213158763935" />
      <inertia
        ixx="2.65673245579854E-08"
        ixy="-1.06533216603001E-19"
        ixz="2.78671992800187E-24"
        iyy="2.71046184723304E-08"
        iyz="2.33090006156728E-24"
        izz="4.12443201011792E-08" />
    </inertial>
    <visual>
      <origin
        xyz="0 0 0"
        rpy="0 0 0" />
      <geometry>
        <mesh
          filename="package://LRMate-200iD/meshes/j4.stl" />
      </geometry>
      <material
        name="">
        <color
          rgba="0.529411764705882 0.549019607843137 0.549019607843137 1" />
      </material>
    </visual>
    <collision>
      <origin
        xyz="0 0 0"
        rpy="0 0 0" />
      <geometry>
        <mesh
          filename="package://LRMate-200iD/meshes/j4.stl" />
      </geometry>
    </collision>
  </link>
  <joint
    name="J4"
    type="revolute">
    <origin
      xyz="0.088001 0 0.035027"
      rpy="0 0 0" />
    <parent
      link="J3" />
    <child
      link="J4" />
    <axis
      xyz="-1 0 0" />
    <limit
      lower="-3.1416"
      upper="3.1416"
      effort="0"
      velocity="0" />
  </joint>
  <link
    name="J5">
    <inertial>
      <origin
        xyz="0.00558036021420949 0.00377232979957495 -7.3630592830165E-05"
        rpy="0 0 0" />
      <mass
        value="0.353025788503532" />
      <inertia
        ixx="0.000244952491429944"
        ixy="1.18235510369031E-05"
        ixz="2.00257550541786E-07"
        iyy="0.000329223967339488"
        iyz="-1.14348885550025E-08"
        izz="0.000304635405669297" />
    </inertial>
    <visual>
      <origin
        xyz="0 0 0"
        rpy="0 0 0" />
      <geometry>
        <mesh
          filename="package://LRMate-200iD/meshes/j5.stl" />
      </geometry>
      <material
        name="">
        <color
          rgba="0.792156862745098 0.819607843137255 0.933333333333333 1" />
      </material>
    </visual>
    <collision>
      <origin
        xyz="0 0 0"
        rpy="0 0 0" />
      <geometry>
        <mesh
          filename="package://LRMate-200iD/meshes/j5.stl" />
      </geometry>
    </collision>
  </link>
  <joint
    name="J5"
    type="revolute">
    <origin
      xyz="0.2454 0 0"
      rpy="0 0 0" />
    <parent
      link="J4" />
    <child
      link="J5" />
    <axis
      xyz="0 -1 0" />
    <limit
      lower="-2.1817"
      upper="2.1817"
      effort="0"
      velocity="0" />
  </joint>
  <link
    name="J6">
    <inertial>
      <origin
        xyz="0.0125090964713958 -2.92517121636138E-11 -2.78925301440261E-05"
        rpy="0 0 0" />
      <mass
        value="0.0932131759055648" />
      <inertia
        ixx="5.26544489983036E-05"
        ixy="3.91455544631797E-14"
        ixz="3.43660691192587E-08"
        iyy="3.15869569838093E-05"
        iyz="2.75690405322797E-11"
        izz="3.16281274062994E-05" />
    </inertial>
    <visual>
      <origin
        xyz="0 0 0"
        rpy="0 0 0" />
      <geometry>
        <mesh
          filename="package://LRMate-200iD/meshes/j6.stl" />
      </geometry>
      <material
        name="">
        <color
          rgba="0.792156862745098 0.819607843137255 0.933333333333333 1" />
      </material>
    </visual>
    <collision>
      <origin
        xyz="0 0 0"
        rpy="0 0 0" />
      <geometry>
        <mesh
          filename="package://LRMate-200iD/meshes/j6.stl" />
      </geometry>
    </collision>
  </link>
  <joint
    name="J6"
    type="revolute">
    <origin
      xyz="0.05 0 0"
      rpy="1.5708 0 0" />
    <parent
      link="J5" />
    <child
      link="J6" />
    <axis
      xyz="-1 0 0" />
    <limit
      lower="0"
      upper="0"
      effort="0"
      velocity="0" />
  </joint>
</robot>